<?xml version="1.0"?>
<robot xmlns:xacro="http://www.ros.org/wiki/xacro">
 
  <xacro:include filename="$(find pal_robotiq_epick_description)/urdf/robotiq_epick_gripper.transmission.xacro" />
  <xacro:include filename="$(find pal_robotiq_epick_description)/urdf/grasping_frames.xacro" />
  <xacro:property name="joint_lower_limit" value="0.0" />
  <xacro:property name="joint_upper_limit" value="0.055" />

  <xacro:macro name="epick_hand" params="prefix parent *origin">
    
    <joint name="${prefix}base_joint" type="fixed">
      <parent link="${parent}"/>
      <child link="${prefix}coupler_link"/>
      <xacro:insert_block name="origin" />
    </joint>

    <link name="${prefix}coupler_link">
      <visual>
          <origin xyz="0 0 0.0" rpy="3.1416 0 0" />
          <geometry>
              <mesh filename="package://pal_robotiq_epick_description/meshes/visual/pal_robotiq_coupling.stl"/>
          </geometry>
          <material name="">
            <color rgba="1 1 1 1"/>
          </material>
      </visual>
      <collision>
          <origin xyz="0 0 0.0" rpy="3.1416 0 0" />
          <geometry>
              <mesh filename="package://pal_robotiq_epick_description/meshes/visual/pal_robotiq_coupling.stl"/>
          </geometry>
      </collision>
      <inertial>
          <mass value="0.2" />
          <origin xyz="0.0 0.0 -0.01" />
          <inertia ixx = "0.000001" ixy = "0.000000" ixz = "0.000000"
                   iyx = "0.000000" iyy = "0.000001" iyz = "0.000000"
                   izx = "0.000000" izy = "0.000000" izz = "0.000001" />
      </inertial>
    </link>

    <joint name="${prefix}coupler_joint" type="fixed">
      <parent link="${prefix}coupler_link"/>
      <child link="${prefix}base_link"/>
      <origin xyz="0 0 ${0.0273}" rpy="0 0 -${3.1416/2}"/>      
    </joint>

    <link name="${prefix}base_link">
      <inertial>
        <mass value="0.745" />
        <origin xyz="0 0.0 0.055" rpy="0 0 0" />
        <inertia ixx="0.003084" ixy="0.0" ixz="0.0" iyy="0.002999" iyz="0.0" izz="0.000546" />
      </inertial>
      <visual>
        <origin xyz="0 0 0.095" rpy="0 0 0"/>
        <geometry>          
          <mesh filename="package://pal_robotiq_epick_description/meshes/visual/robotiq_epick.dae" scale="0.001 0.001 0.001"/>          
        </geometry>
        <material name="">
          <color rgba="1 1 1 1"/>
        </material>        
      </visual>
      <visual>        
        <origin xyz="0 0 ${0.015+0.095}" rpy="0 0 0"/>
        <geometry>          
          <cylinder radius="0.006" length="0.03"/>
        </geometry>
        <material name="">
          <color rgba="1 1 1 1"/>
        </material>        
      </visual>      
      <collision>
        <!-- -0.095 + 0.102/2 = -0.044-->
        <origin xyz="0 0 ${-0.044+0.095+0.014}" rpy="0 0 0"/>
        <geometry>          
          <cylinder radius="0.044" length="0.13"/>
        </geometry>       
      </collision>      
<!--       <collision>        
        <origin xyz="0 0 ${0.008+0.095}" rpy="0 0 0"/>
        <geometry>          
          <cylinder radius="0.006" length="0.016"/>
        </geometry>
        <material name="">
          <color rgba="1 1 1 1"/>
        </material>        
      </collision>  -->     
    </link>

    <joint name="${prefix}vacuum_joint" type="prismatic">
      <parent link="${prefix}base_link"/>
      <child link="${prefix}end_effector"/>
      <origin xyz="0 0 0.13" rpy="0 0 0"/>
      <axis xyz="0 0 1" />
      <limit lower="-0.01" upper="0.0" velocity="2.0" effort="1000"/>
      <dynamics damping="0.1" friction="0.01"/>
    </joint>

    <link name="${prefix}end_effector">
      <gravity>0</gravity>
      <visual>
        <origin rpy="0 0 0.005" xyz="0 0 0"/>
        <geometry>
          <cylinder radius="0.0225" length="0.01"/>          
        </geometry>
        <material name="transparent">
          <color rgba="0.5 0.5 0.5 0.7"/>
        </material>
      </visual>
      <inertial>
        <origin rpy="0 0 0" xyz="0 0 0"/>
        <mass value="0.0001"/>
        <inertia ixx="1e-08" ixy="0" ixz="0" iyy="1e-08" iyz="0" izz="1e-08"/>
      </inertial>
    </link>

    <xacro:pal_robotiq_grasping_frames prefix="${prefix}" xyz="0 0 0.135"/>

    <xacro:robotiq_epick_gripper_transmission prefix="${prefix}"/>
  </xacro:macro>
</robot>
